<?xml version="1.0" encoding="utf-8"?>
<!-- This URDF was automatically created by SolidWorks to URDF Exporter! Originally created by Stephen Brawner (brawner@gmail.com) 
     Commit Version: 1.5.1-0-g916b5db  Build Version: 1.5.7152.31018
     For more information, please see http://wiki.ros.org/sw_urdf_exporter -->
<robot
  name="new_robot_description">
  <link
    name="base_link">
    <inertial>
      <origin
        xyz="-0.0362631630213368 -0.0184368132164093 0.0180391285843125"
        rpy="0 0 0" />
      <mass
        value="11.8935575217908" />
      <inertia
        ixx="0.16948570883081"
        ixy="0.00171944073324637"
        ixz="0.0110641871915267"
        iyy="0.407650272383018"
        iyz="-0.00058670872412833"
        izz="0.421654763423977" />
    </inertial>
    <visual>
      <origin
        xyz="0 0 0"
        rpy="0 0 0" />
      <geometry>
        <mesh
          filename="package://new_robot_description/meshes/base_link.STL" />
      </geometry>
      <material
        name="">
        <color
          rgba="0.752941176470588 0.752941176470588 0.752941176470588 1" />
      </material>
    </visual>
    <collision>
      <origin
        xyz="0 0 0"
        rpy="0 0 0" />
      <geometry>
        <mesh
          filename="package://new_robot_description/meshes/base_link.STL" />
      </geometry>
    </collision>
  </link>
  <link
    name="FR">
    <inertial>
      <origin
        xyz="1.7499E-08 -9.006E-09 -0.046913"
        rpy="0 0 0" />
      <mass
        value="4" />
      <inertia
        ixx="0.0044232"
        ixy="-3.0571E-11"
        ixz="3.8718E-11"
        iyy="0.0044232"
        iyz="-9.9281E-10"
        izz="0.0077374" />
    </inertial>
    <visual>
      <origin
        xyz="0 0 0"
        rpy="0 0 0" />
      <geometry>
        <mesh
          filename="package://new_robot_description/meshes/FR.STL" />
      </geometry>
      <material
        name="">
        <color
          rgba="0.79216 0.81961 0.93333 1" />
      </material>
    </visual>
    <collision>
      <origin
        xyz="0 0 0"
        rpy="0 0 0" />
      <geometry>
        <mesh
          filename="package://new_robot_description/meshes/FR.STL" />
      </geometry>
    </collision>
  </link>
  <joint
    name="joint_FR"
    type="continuous">
    <origin
      xyz="0.12696 -0.15232 -0.055677"
      rpy="1.5708 -0.41309 3.1416" />
    <parent
      link="base_link" />
    <child
      link="FR" />
    <axis
      xyz="0 0 1" />
  </joint>
  <link
    name="FL">
    <inertial>
      <origin
        xyz="1.7499E-08 -9.006E-09 -0.046913"
        rpy="0 0 0" />
      <mass
        value="4" />
      <inertia
        ixx="0.0044232"
        ixy="-3.0571E-11"
        ixz="3.8718E-11"
        iyy="0.0044232"
        iyz="-9.928E-10"
        izz="0.0077374" />
    </inertial>
    <visual>
      <origin
        xyz="0 0 0"
        rpy="0 0 0" />
      <geometry>
        <mesh
          filename="package://new_robot_description/meshes/FL.STL" />
      </geometry>
      <material
        name="">
        <color
          rgba="0.79216 0.81961 0.93333 1" />
      </material>
    </visual>
    <collision>
      <origin
        xyz="0 0 0"
        rpy="0 0 0" />
      <geometry>
        <mesh
          filename="package://new_robot_description/meshes/FL.STL" />
      </geometry>
    </collision>
  </link>
  <joint
    name="joint_FL"
    type="continuous">
    <origin
      xyz="0.12696 0.11424 -0.055677"
      rpy="1.5708 -0.090814 0" />
    <parent
      link="base_link" />
    <child
      link="FL" />
    <axis
      xyz="0 0 1" />
  </joint>
  <link
    name="BR">
    <inertial>
      <origin
        xyz="1.7499E-08 -9.006E-09 -0.046913"
        rpy="0 0 0" />
      <mass
        value="4" />
      <inertia
        ixx="0.0044232"
        ixy="-3.0571E-11"
        ixz="3.8718E-11"
        iyy="0.0044232"
        iyz="-9.928E-10"
        izz="0.0077374" />
    </inertial>
    <visual>
      <origin
        xyz="0 0 0"
        rpy="0 0 0" />
      <geometry>
        <mesh
          filename="package://new_robot_description/meshes/BR.STL" />
      </geometry>
      <material
        name="">
        <color
          rgba="0.79216 0.81961 0.93333 1" />
      </material>
    </visual>
    <collision>
      <origin
        xyz="0 0 0"
        rpy="0 0 0" />
      <geometry>
        <mesh
          filename="package://new_robot_description/meshes/BR.STL" />
      </geometry>
    </collision>
  </link>
  <joint
    name="joint_BR"
    type="continuous">
    <origin
      xyz="-0.15304 -0.15232 -0.055677"
      rpy="1.5708 0.052512 -3.1416" />
    <parent
      link="base_link" />
    <child
      link="BR" />
    <axis
      xyz="0 0 1" />
  </joint>
  <link
    name="BL">
    <inertial>
      <origin
        xyz="1.7499E-08 -9.006E-09 -0.046913"
        rpy="0 0 0" />
      <mass
        value="4" />
      <inertia
        ixx="0.0044232"
        ixy="-3.0571E-11"
        ixz="3.8718E-11"
        iyy="0.0044232"
        iyz="-9.928E-10"
        izz="0.0077374" />
    </inertial>
    <visual>
      <origin
        xyz="0 0 0"
        rpy="0 0 0" />
      <geometry>
        <mesh
          filename="package://new_robot_description/meshes/BL.STL" />
      </geometry>
      <material
        name="">
        <color
          rgba="0.79216 0.81961 0.93333 1" />
      </material>
    </visual>
    <collision>
      <origin
        xyz="0 0 0"
        rpy="0 0 0" />
      <geometry>
        <mesh
          filename="package://new_robot_description/meshes/BL.STL" />
      </geometry>
    </collision>
  </link>
  <joint
    name="joint_BL"
    type="continuous">
    <origin
      xyz="-0.15304 0.11424 -0.055677"
      rpy="1.5708 -0.042013 0" />
    <parent
      link="base_link" />
    <child
      link="BL" />
    <axis
      xyz="0 0 1" />
  </joint>
</robot>
