<?xml version="1.0"?>

<robot
  name="patrol_base"
  xmlns:xacro="http://www.ros.org/wiki/xacro"
  >

<xacro:include filename="$(find patrol_v3)/urdf/patrol_2D.gazebo" />
  <xacro:property name="cameraSize" value="0.05"/>
  <xacro:property name="cameraMass" value="0.1"/>
  <xacro:arg name="gpu" default="false"/>
  <xacro:property name="gpu" value="$(arg gpu)" />

  <link  name="base_link" />


  <link
    name="chassis">
    <inertial>
      <origin
        xyz="-0.05588 -0.021836 0.11979"
        rpy="0 0 0" />
      <mass
        value="60" />
      <inertia
        ixx="0.2844"
        ixy="0.00042222"
        ixz="0.045634"
        iyy="0.36594"
        iyz="-0.000122"
        izz="0.4528" />
    </inertial>
    <visual>
      <origin
        xyz="0 0 0"
        rpy="0 0 0" />
      <geometry>
        <mesh
          filename="package://patrol_v3/meshes/chassis.STL" />
      </geometry>
      <material
        name="">
        <color
          rgba="0.79216 0.81961 0.93333 1" />
      </material>
    </visual>
    <collision>
      <origin
        xyz="0 0 0"
        rpy="0 0 0" />
      <geometry>
        <mesh
          filename="package://patrol_v3/meshes/chassis.STL" />
      </geometry>
    </collision>
  </link>

  <joint
    name="Jchassis"
    type="fixed">
    <origin
      xyz="0 0 0.2500"
      rpy="0 0 0" />
    <parent
      link="base_link" />
    <child
      link="chassis" />
    <axis
      xyz="0 0 0" />
  </joint>

  <link
    name="FL">
    <inertial>
      <origin
        xyz="-3.5376E-06 4.1624E-06 -0.041529"
        rpy="0 0 0" />
      <mass
        value="1.1763" />
      <inertia
        ixx="0.0072471"
        ixy="2.8453E-07"
        ixz="1.5822E-07"
        iyy="0.0072464"
        iyz="-6.4823E-07"
        izz="0.012903" />
    </inertial>
    <visual>
      <origin
        xyz="0 0 0"
        rpy="0 0 0" />
      <geometry>
        <mesh
          filename="package://patrol_v3/meshes/FL.STL" />
      </geometry>
      <material
        name="">
        <color
          rgba="0.29804 0.29804 0.29804 1" />
      </material>
    </visual>
    <collision>
      <origin
        xyz="0 0 0"
        rpy="0 0 0" />
      <geometry>
        <mesh
          filename="package://patrol_v3/meshes/FL.STL" />
      </geometry>
    </collision>
  </link>
  <joint
    name="FLJ"
    type="continuous">
    <origin
      xyz="0.29133 0.23565 -0.1178"
      rpy="1.5708 -1.5399 0" />
    <parent
      link="chassis" />
    <child
      link="FL" />
    <axis
      xyz="0 0 -1" />
  </joint>
  <link
    name="FR">
    <inertial>
      <origin
        xyz="-3.4705E-06 4.7858E-06 0.041533"
        rpy="0 0 0" />
      <mass
        value="1.1763" />
      <inertia
        ixx="0.0072471"
        ixy="2.854E-07"
        ixz="1.5817E-07"
        iyy="0.0072464"
        iyz="-6.4816E-07"
        izz="0.012903" />
    </inertial>
    <visual>
      <origin
        xyz="0 0 0"
        rpy="0 0 0" />
      <geometry>
        <mesh
          filename="package://patrol_v3/meshes/FR.STL" />
      </geometry>
      <material
        name="">
        <color
          rgba="0.29804 0.29804 0.29804 1" />
      </material>
    </visual>
    <collision>
      <origin
        xyz="0 0 0"
        rpy="0 0 0" />
      <geometry>
        <mesh
          filename="package://patrol_v3/meshes/FR.STL" />
      </geometry>
    </collision>
  </link>
  <joint
    name="FRJ"
    type="continuous">
    <origin
      xyz="0.29133 -0.27837 -0.1178"
      rpy="-1.5708 -0.32548 3.1416" />
    <parent
      link="chassis" />
    <child
      link="FR" />
    <axis
      xyz="0 0 -1" />
  </joint>
  <link
    name="RL">
    <inertial>
      <origin
        xyz="-3.5397E-06 4.7909E-06 -0.041529"
        rpy="0 0 0" />
      <mass
        value="1.1763" />
      <inertia
        ixx="0.0072471"
        ixy="2.8444E-07"
        ixz="1.5824E-07"
        iyy="0.0072464"
        iyz="-6.4835E-07"
        izz="0.012903" />
    </inertial>
    <visual>
      <origin
        xyz="0 0 0"
        rpy="0 0 0" />
      <geometry>
        <mesh
          filename="package://patrol_v3/meshes/RL.STL" />
      </geometry>
      <material
        name="">
        <color
          rgba="0.29804 0.29804 0.29804 1" />
      </material>
    </visual>
    <collision>
      <origin
        xyz="0 0 0"
        rpy="0 0 0" />
      <geometry>
        <mesh
          filename="package://patrol_v3/meshes/RL.STL" />
      </geometry>
    </collision>
  </link>
  <joint
    name="RLJ"
    type="continuous">
    <origin
      xyz="-0.34867 0.23181 -0.1178"
      rpy="-1.5708 -0.47562 3.1416" />
    <parent
      link="chassis" />
    <child
      link="RL" />
    <axis
      xyz="0 0 -1" />
  </joint>
  <link
    name="RR">
    <inertial>
      <origin
        xyz="-3.5816E-06 4.783E-06 0.041533"
        rpy="0 0 0" />
      <mass
        value="1.1763" />
      <inertia
        ixx="0.0072471"
        ixy="2.8396E-07"
        ixz="1.5827E-07"
        iyy="0.0072464"
        iyz="-6.4852E-07"
        izz="0.012903" />
    </inertial>
    <visual>
      <origin
        xyz="0 0 0"
        rpy="0 0 0" />
      <geometry>
        <mesh
          filename="package://patrol_v3/meshes/RR.STL" />
      </geometry>
      <material
        name="">
        <color
          rgba="0.29804 0.29804 0.29804 1" />
      </material>
    </visual>
    <collision>
      <origin
        xyz="0 0 0"
        rpy="0 0 0" />
      <geometry>
        <mesh
          filename="package://patrol_v3/meshes/RR.STL" />
      </geometry>
    </collision>
  </link>
  <joint
    name="RRJ"
    type="continuous">
    <origin
      xyz="-0.34867 -0.28222 -0.1178"
      rpy="-1.5708 0.73947 -3.1416" />
    <parent
      link="chassis" />
    <child
      link="RR" />
    <axis
      xyz="0 0 -1" />
  </joint>

      <joint
    name="lidar_joint"
    type="fixed">
    <origin
      xyz="0.0 0.0 0.07"
      rpy="-3.1407 0 0 " />
    <parent
      link="base_link" />
    <child
      link="lidar" />
  </joint>

  <link  name="lidar" />


  <xacro:include filename="$(find velodyne_description)/urdf/VLP-16.urdf.xacro"/>
  <VLP-16 parent="base_link" name="velodyne" topic="/velodyne_points" hz="10" samples="440" gpu="${gpu}" min_angle="-1.9198" max_angle="1.9198">
    <origin xyz="0.60383 -0.023174 0.200096" rpy="0 0 0" />
  </VLP-16>

<transmission name="front_left_trans">
  <type>transmission_interface/SimpleTransmission</type>
  <joint name="FLJ">
    <hardwareInterface>hardware_interface/VelocityJointInterface</hardwareInterface>
  </joint>
  <actuator name="Front_Left_Motor">
    <hardwareInterface>hardware_interface/VelocityJointInterface</hardwareInterface>
    <mechanicalReduction>1</mechanicalReduction>
  </actuator>
</transmission>

<transmission name="front_right_trans">
  <type>transmission_interface/SimpleTransmission</type>
  <joint name="FRJ">
    <hardwareInterface>hardware_interface/VelocityJointInterface</hardwareInterface>
  </joint>
  <actuator name="Front_Right_Motor">
    <hardwareInterface>hardware_interface/VelocityJointInterface</hardwareInterface>
    <mechanicalReduction>1</mechanicalReduction>
  </actuator>
</transmission>

<transmission name="back_left_trans">
  <type>transmission_interface/SimpleTransmission</type>
  <joint name="RLJ">
    <hardwareInterface>hardware_interface/VelocityJointInterface</hardwareInterface>
  </joint>
  <actuator name="Back_Left_Motor">
    <hardwareInterface>hardware_interface/VelocityJointInterface</hardwareInterface>
    <mechanicalReduction>1</mechanicalReduction>
  </actuator>
</transmission>

<transmission name="back_right_trans">
  <type>transmission_interface/SimpleTransmission</type>
  <joint name="RRJ">
    <hardwareInterface>hardware_interface/VelocityJointInterface</hardwareInterface>
  </joint>
  <actuator name="Back_Right_Motor">
    <hardwareInterface>hardware_interface/VelocityJointInterface</hardwareInterface>
    <mechanicalReduction>1</mechanicalReduction>
  </actuator>
</transmission>

</robot>